<?xml version="1.0" ?>
<!-- =================================================================================== -->
<!-- |    This document was autogenerated by xacro from model.urdf.xacro               | -->
<!-- |    EDITING THIS FILE BY HAND IS NOT RECOMMENDED                                 | -->
<!-- =================================================================================== -->
<robot name="5dof_robot_manipulator">
  <!-- Specify some standard inertial calculations https://en.wikipedia.org/wiki/List_of_moments_of_inertia -->
  <!-- These make use of xacro's mathematical functionality -->
  <gazebo>
    <plugin filename="libgazebo_ros2_control.so" name="gazebo_ros2_control">
      <parameters>/home/bgb_6342/ws_manipulator/src/manipulator/config/ros2_controllers.yaml</parameters>
    </plugin>
  </gazebo>
  <!-- COLOR DEFINITIONS -->
  <material name="blue">
    <color rgba="0 0 1 1"/>
  </material>
  <material name="dark_blue">
    <color rgba="0 0 0.5 1"/>
  </material>
  <material name="black">
    <color rgba="0 0 0 1"/>
  </material>
  <material name="white">
    <color rgba="1 1 1 1"/>
  </material>
  <material name="grey">
    <color rgba="0.5 0.5 0.5 1"/>
  </material>
  <material name="dark_grey">
    <color rgba="0.25 0.25 0.25 1"/>
  </material>
  <!-- We add a dummy world link and a fixed joint to fix our robot to the world -->
  <!-- This is important for gazebo simulation -->
  <link name="world"/>
  <joint name="fixed_joint" type="fixed">
    <origin rpy="0 0 0" xyz="0 0 0.1"/>
    <parent link="world"/>
    <child link="base_link"/>
  </joint>
  <link name="base_link">
    <visual>
      <geometry>
        <cylinder length="0.2" radius="0.1"/>
      </geometry>
      <origin rpy="0 0 0" xyz="0 0 0"/>
      <material name="black"/>
    </visual>
    <collision>
      <geometry>
        <cylinder length="0.2" radius="0.1"/>
      </geometry>
      <origin rpy="0 0 0" xyz="0 0 0"/>
    </collision>
    <inertial>
      <origin rpy="0 0 0" xyz="0 0 0"/>
      <mass value="0.5"/>
      <inertia ixx="0.002916666666666667" ixy="0.0" ixz="0.0" iyy="0.002916666666666667" iyz="0.0" izz="0.0025000000000000005"/>
    </inertial>
  </link>
  <gazebo reference="base_link">
    <material>Gazebo/black</material>
  </gazebo>
  <joint name="joint_1" type="revolute">
    <parent link="base_link"/>
    <child link="link_1"/>
    <origin rpy="0 0 0" xyz="0 0 0.1"/>
    <axis xyz="0 0 1"/>
    <limit effort="300" lower="-3.141593" upper="3.141593" velocity="2.0"/>
  </joint>
  <link name="link_1">
    <visual>
      <geometry>
        <cylinder length="0.215" radius="0.05"/>
      </geometry>
      <origin rpy="0 0 0" xyz="0 0 0.1075"/>
      <material name="dark_blue"/>
    </visual>
    <collision>
      <geometry>
        <cylinder length="0.215" radius="0.05"/>
      </geometry>
      <origin rpy="0 0 0" xyz="0 0 0.1075"/>
    </collision>
    <inertial>
      <origin rpy="0 0 0" xyz="0 0 0.1075"/>
      <mass value="0.5"/>
      <inertia ixx="0.0022385416666666665" ixy="0.0" ixz="0.0" iyy="0.0022385416666666665" iyz="0.0" izz="0.0006250000000000001"/>
    </inertial>
  </link>
  <gazebo reference="link_1">
    <material>Gazebo/dark_blue</material>
  </gazebo>
  <joint name="joint_2" type="revolute">
    <parent link="link_1"/>
    <child link="link_2"/>
    <origin rpy="0 -1.570796 0" xyz="-0.05 0 0.165"/>
    <axis xyz="0 0 1"/>
    <limit effort="300" lower="-3.141593" upper="3.141593" velocity="2.0"/>
  </joint>
  <link name="link_2">
    <visual>
      <geometry>
        <cylinder length="0.51" radius="0.05"/>
      </geometry>
      <origin rpy="0 1.570796 0" xyz="0.205 0 0.05"/>
      <material name="dark_grey"/>
    </visual>
    <collision>
      <geometry>
        <cylinder length="0.51" radius="0.05"/>
      </geometry>
      <origin rpy="0 1.570796 0" xyz="0.205 0 0.05"/>
    </collision>
    <inertial>
      <origin rpy="0 1.570796 0" xyz="0.205 0 0.05"/>
      <mass value="0.5"/>
      <inertia ixx="0.01115" ixy="0.0" ixz="0.0" iyy="0.01115" iyz="0.0" izz="0.0006250000000000001"/>
    </inertial>
  </link>
  <gazebo reference="link_2">
    <material>Gazebo/dark_grey</material>
  </gazebo>
  <joint name="joint_3" type="revolute">
    <parent link="link_2"/>
    <child link="link_3"/>
    <origin rpy="0 0 0" xyz="0.41 0 0"/>
    <axis xyz="0 0 1"/>
    <limit effort="300" lower="-3.141593" upper="3.141593" velocity="2.0"/>
  </joint>
  <link name="link_3">
    <visual>
      <geometry>
        <cylinder length="0.53" radius="0.05"/>
      </geometry>
      <origin rpy="0 1.570796 0" xyz="0.215 0 -0.05"/>
      <material name="dark_blue"/>
    </visual>
    <collision>
      <geometry>
        <cylinder length="0.53" radius="0.05"/>
      </geometry>
      <origin rpy="0 1.570796 0" xyz="0.215 0 -0.05"/>
    </collision>
    <inertial>
      <origin rpy="0 1.570796 0" xyz="0.215 0 -0.05"/>
      <mass value="0.5"/>
      <inertia ixx="0.012016666666666669" ixy="0.0" ixz="0.0" iyy="0.012016666666666669" iyz="0.0" izz="0.0006250000000000001"/>
    </inertial>
  </link>
  <gazebo reference="link_3">
    <material>Gazebo/dark_blue</material>
  </gazebo>
  <joint name="joint_4" type="revolute">
    <parent link="link_3"/>
    <child link="link_4"/>
    <origin rpy="0 0 0" xyz="0.43 0 0"/>
    <axis xyz="0 0 1"/>
    <limit effort="300" lower="-3.141593" upper="3.141593" velocity="2.0"/>
  </joint>
  <link name="link_4">
    <visual>
      <geometry>
        <cylinder length="0.115" radius="0.05"/>
      </geometry>
      <origin rpy="0 1.570796 0" xyz="0.0075 0 0.05"/>
      <material name="dark_grey"/>
    </visual>
    <collision>
      <geometry>
        <cylinder length="0.115" radius="0.05"/>
      </geometry>
      <origin rpy="0 1.570796 0" xyz="0.0075 0 0.05"/>
    </collision>
    <inertial>
      <origin rpy="0 1.570796 0" xyz="0.0075 0 0.05"/>
      <mass value="0.5"/>
      <inertia ixx="0.0008635416666666666" ixy="0.0" ixz="0.0" iyy="0.0008635416666666666" iyz="0.0" izz="0.0006250000000000001"/>
    </inertial>
  </link>
  <gazebo reference="link_4">
    <material>Gazebo/dark_grey</material>
  </gazebo>
  <joint name="joint_5" type="revolute">
    <parent link="link_4"/>
    <child link="link_5"/>
    <origin rpy="0 1.570796 0" xyz="0.065 0 0.05"/>
    <axis xyz="0 0 1"/>
    <limit effort="300" lower="-3.141593" upper="3.141593" velocity="2.0"/>
  </joint>
  <link name="link_5">
    <visual>
      <geometry>
        <cylinder length="0.08" radius="0.05"/>
      </geometry>
      <origin rpy="0 0 0" xyz="0 0 0.04"/>
      <material name="dark_blue"/>
    </visual>
    <collision>
      <geometry>
        <cylinder length="0.08" radius="0.05"/>
      </geometry>
      <origin rpy="0 0 0" xyz="0 0 0.04"/>
    </collision>
    <inertial>
      <origin rpy="0 0 0" xyz="0 0 0.04"/>
      <mass value="0.5"/>
      <inertia ixx="0.0005791666666666667" ixy="0.0" ixz="0.0" iyy="0.0005791666666666667" iyz="0.0" izz="0.0006250000000000001"/>
    </inertial>
  </link>
  <gazebo reference="link_5">
    <material>Gazebo/dark_blue</material>
  </gazebo>
  <ros2_control name="GazeboSystem" type="system">
    <hardware>
      <plugin>gazebo_ros2_control/GazeboSystem</plugin>
    </hardware>
    <joint name="joint_1">
      <command_interface name="position"/>
      <state_interface name="position"/>
      <state_interface name="velocity"/>
    </joint>
    <joint name="joint_2">
      <command_interface name="position"/>
      <state_interface name="position"/>
      <state_interface name="velocity"/>
    </joint>
    <joint name="joint_3">
      <command_interface name="position"/>
      <state_interface name="position"/>
      <state_interface name="velocity"/>
    </joint>
    <joint name="joint_4">
      <command_interface name="position"/>
      <state_interface name="position"/>
      <state_interface name="velocity"/>
    </joint>
    <joint name="joint_5">
      <command_interface name="position"/>
      <state_interface name="position"/>
      <state_interface name="velocity"/>
    </joint>
  </ros2_control>
</robot>
